Run: 3
Defaulting to user installation because normal site-packages is not writeable
Obtaining file:///common/ketrong/tpotexp/tpot2/tpot2

[notice] A new release of pip is available: 24.2 -> 24.3.1
[notice] To update, run: pip3.12 install --upgrade pip
ERROR: file:///common/ketrong/tpotexp/tpot2/tpot2 does not appear to be a Python project: neither 'setup.py' nor 'pyproject.toml' found.
Defaulting to user installation because normal site-packages is not writeable
Collecting skrebate>=0.3.4 (from -r /common/ketrong/tpotexp/tpot2/ImputerExperiments/requirements_.txt (line 1))
  Using cached skrebate-0.62.tar.gz (19 kB)

[notice] A new release of pip is available: 24.2 -> 24.3.1
[notice] To update, run: pip3.12 install --upgrade pip
ERROR: Exception:
Traceback (most recent call last):
  File "/hpc/apps/python3/3.12.7/lib/python3.12/site-packages/pip/_vendor/urllib3/response.py", line 438, in _error_catcher
    yield
  File "/hpc/apps/python3/3.12.7/lib/python3.12/site-packages/pip/_vendor/urllib3/response.py", line 561, in read
    data = self._fp_read(amt) if not fp_closed else b""
           ^^^^^^^^^^^^^^^^^^
  File "/hpc/apps/python3/3.12.7/lib/python3.12/site-packages/pip/_vendor/urllib3/response.py", line 527, in _fp_read
    return self._fp.read(amt) if amt is not None else self._fp.read()
           ^^^^^^^^^^^^^^^^^^
OSError: [Errno 116] Stale file handle

During handling of the above exception, another exception occurred:

Traceback (most recent call last):
  File "/hpc/apps/python3/3.12.7/lib/python3.12/site-packages/pip/_internal/cli/base_command.py", line 105, in _run_wrapper
    status = _inner_run()
             ^^^^^^^^^^^^
  File "/hpc/apps/python3/3.12.7/lib/python3.12/site-packages/pip/_internal/cli/base_command.py", line 96, in _inner_run
    return self.run(options, args)
           ^^^^^^^^^^^^^^^^^^^^^^^
  File "/hpc/apps/python3/3.12.7/lib/python3.12/site-packages/pip/_internal/cli/req_command.py", line 67, in wrapper
    return func(self, options, args)
           ^^^^^^^^^^^^^^^^^^^^^^^^^
  File "/hpc/apps/python3/3.12.7/lib/python3.12/site-packages/pip/_internal/commands/install.py", line 379, in run
    requirement_set = resolver.resolve(
                      ^^^^^^^^^^^^^^^^^
  File "/hpc/apps/python3/3.12.7/lib/python3.12/site-packages/pip/_internal/resolution/resolvelib/resolver.py", line 95, in resolve
    result = self._result = resolver.resolve(
                            ^^^^^^^^^^^^^^^^^
  File "/hpc/apps/python3/3.12.7/lib/python3.12/site-packages/pip/_vendor/resolvelib/resolvers.py", line 546, in resolve
    state = resolution.resolve(requirements, max_rounds=max_rounds)
            ^^^^^^^^^^^^^^^^^^^^^^^^^^^^^^^^^^^^^^^^^^^^^^^^^^^^^^^
  File "/hpc/apps/python3/3.12.7/lib/python3.12/site-packages/pip/_vendor/resolvelib/resolvers.py", line 397, in resolve
    self._add_to_criteria(self.state.criteria, r, parent=None)
  File "/hpc/apps/python3/3.12.7/lib/python3.12/site-packages/pip/_vendor/resolvelib/resolvers.py", line 173, in _add_to_criteria
    if not criterion.candidates:
           ^^^^^^^^^^^^^^^^^^^^
  File "/hpc/apps/python3/3.12.7/lib/python3.12/site-packages/pip/_vendor/resolvelib/structs.py", line 156, in __bool__
    return bool(self._sequence)
           ^^^^^^^^^^^^^^^^^^^^
  File "/hpc/apps/python3/3.12.7/lib/python3.12/site-packages/pip/_internal/resolution/resolvelib/found_candidates.py", line 174, in __bool__
    return any(self)
           ^^^^^^^^^
  File "/hpc/apps/python3/3.12.7/lib/python3.12/site-packages/pip/_internal/resolution/resolvelib/found_candidates.py", line 162, in <genexpr>
    return (c for c in iterator if id(c) not in self._incompatible_ids)
                       ^^^^^^^^
  File "/hpc/apps/python3/3.12.7/lib/python3.12/site-packages/pip/_internal/resolution/resolvelib/found_candidates.py", line 53, in _iter_built
    candidate = func()
                ^^^^^^
  File "/hpc/apps/python3/3.12.7/lib/python3.12/site-packages/pip/_internal/resolution/resolvelib/factory.py", line 186, in _make_candidate_from_link
    base: Optional[BaseCandidate] = self._make_base_candidate_from_link(
                                    ^^^^^^^^^^^^^^^^^^^^^^^^^^^^^^^^^^^^
  File "/hpc/apps/python3/3.12.7/lib/python3.12/site-packages/pip/_internal/resolution/resolvelib/factory.py", line 232, in _make_base_candidate_from_link
    self._link_candidate_cache[link] = LinkCandidate(
                                       ^^^^^^^^^^^^^^
  File "/hpc/apps/python3/3.12.7/lib/python3.12/site-packages/pip/_internal/resolution/resolvelib/candidates.py", line 303, in __init__
    super().__init__(
  File "/hpc/apps/python3/3.12.7/lib/python3.12/site-packages/pip/_internal/resolution/resolvelib/candidates.py", line 158, in __init__
    self.dist = self._prepare()
                ^^^^^^^^^^^^^^^
  File "/hpc/apps/python3/3.12.7/lib/python3.12/site-packages/pip/_internal/resolution/resolvelib/candidates.py", line 235, in _prepare
    dist = self._prepare_distribution()
           ^^^^^^^^^^^^^^^^^^^^^^^^^^^^
  File "/hpc/apps/python3/3.12.7/lib/python3.12/site-packages/pip/_internal/resolution/resolvelib/candidates.py", line 314, in _prepare_distribution
    return preparer.prepare_linked_requirement(self._ireq, parallel_builds=True)
           ^^^^^^^^^^^^^^^^^^^^^^^^^^^^^^^^^^^^^^^^^^^^^^^^^^^^^^^^^^^^^^^^^^^^^
  File "/hpc/apps/python3/3.12.7/lib/python3.12/site-packages/pip/_internal/operations/prepare.py", line 527, in prepare_linked_requirement
    return self._prepare_linked_requirement(req, parallel_builds)
           ^^^^^^^^^^^^^^^^^^^^^^^^^^^^^^^^^^^^^^^^^^^^^^^^^^^^^^
  File "/hpc/apps/python3/3.12.7/lib/python3.12/site-packages/pip/_internal/operations/prepare.py", line 598, in _prepare_linked_requirement
    local_file = unpack_url(
                 ^^^^^^^^^^^
  File "/hpc/apps/python3/3.12.7/lib/python3.12/site-packages/pip/_internal/operations/prepare.py", line 170, in unpack_url
    file = get_http_url(
           ^^^^^^^^^^^^^
  File "/hpc/apps/python3/3.12.7/lib/python3.12/site-packages/pip/_internal/operations/prepare.py", line 111, in get_http_url
    from_path, content_type = download(link, temp_dir.path)
                              ^^^^^^^^^^^^^^^^^^^^^^^^^^^^^
  File "/hpc/apps/python3/3.12.7/lib/python3.12/site-packages/pip/_internal/network/download.py", line 148, in __call__
    for chunk in chunks:
                 ^^^^^^
  File "/hpc/apps/python3/3.12.7/lib/python3.12/site-packages/pip/_internal/network/utils.py", line 65, in response_chunks
    for chunk in response.raw.stream(
                 ^^^^^^^^^^^^^^^^^^^^
  File "/hpc/apps/python3/3.12.7/lib/python3.12/site-packages/pip/_vendor/urllib3/response.py", line 622, in stream
    data = self.read(amt=amt, decode_content=decode_content)
           ^^^^^^^^^^^^^^^^^^^^^^^^^^^^^^^^^^^^^^^^^^^^^^^^^
  File "/hpc/apps/python3/3.12.7/lib/python3.12/site-packages/pip/_vendor/urllib3/response.py", line 560, in read
    with self._error_catcher():
         ^^^^^^^^^^^^^^^^^^^^^
  File "/hpc/apps/python3/3.12.7/lib/python3.12/contextlib.py", line 158, in __exit__
    self.gen.throw(value)
  File "/hpc/apps/python3/3.12.7/lib/python3.12/site-packages/pip/_vendor/urllib3/response.py", line 455, in _error_catcher
    raise ProtocolError("Connection broken: %r" % e, e)
pip._vendor.urllib3.exceptions.ProtocolError: ("Connection broken: OSError(116, 'Stale file handle')", OSError(116, 'Stale file handle'))
RunStart
python3: can't open file '/common/ketrong/tpotexp/tpot2/ImputerExperiments/mainog.py': [Errno 2] No such file or directory
